Workbook
Name GASTOS: #REF!
Name PPTO: #REF!

Sheet LISTA
A1: OBRA:
A3: Empresa:
C5: LISTADO DE PRECIO DE INSUMOS - Materiales y M.O.
E6: Fecha:
B7: CODIGO | C7: LISTA DE PRECIOS SIN IVA | D7: MARCA | E7: UN | F7: PRECIO
B8: 1 | C8: Jornal Básico Oficial | E8: Hs | F8: 631.9
B9: =B8+1 -> 2 | C9: Jornal Básico Ayudante | E9: Hs | F9: 197.07
B10: =B9+1 -> 3 | C10: Cemento | E10: Kg | F10: 6.15
B11: =B10+1 -> 4 | C11: Arena | E11: M3 | F11: 2890
B12: =B11+1 -> 5 | C12: Piedra | E12: M3 | F12: 3520
B13: =B12+1 -> 6 | C13: Hierro torsionado | E13: Kg | F13: 1562
B14: =B13+1 -> 7 | C14: Mallas sold. de Fe tors | E14: Kg | F14: 695.41
B15: =B14+1 -> 8 | C15: Alambre Negro | E15: Kg | F15: 298
B16: =B15+1 -> 9 | C16: Madera para encofrado | E16: M2 | F16: 478
B17: =B16+1 -> 10 | C17: Cal | E17: Kg | F17: 3.9
B18: =B17+1 -> 11 | C18: Ladrillo Cerámico 8x18x25 | E18: Nº | F18: 64.56
B19: =B18+1 -> 12 | C19: Hidrófugo | E19: Kg | F19: 1662
B20: =B19+1 -> 13 | C20: Techado asfaltico | E20: LTS | F20: 674.5
B21: =B20+1 -> 14 | C21: Pintura asfáltica | E21: Kg | F21: 1080
B22: =B21+1 -> 15
B23: =B22+1 -> 16 | C23: Metal desplegado | E23: Gl | F23: 418.85
B24: =B23+1 -> 17 | C24: Alambre galvanizado Nº 8 | E24: Kg | F24: 3055.32
B25: =B24+1 -> 18 | C25: Clavos | E25: Kg | F25: 360
B26: =B25+1 -> 19 | C26: Chapa Trapezoidal Nº 24 | E26: M2 | F26: 1738
B27: =B26+1 -> 20 | C27: Chapa Trap 1010 Nº 24 Prepintada | E27: M2 | F27: 890
B28: =B27+1 -> 21 | C28: Chapa AU L1 400 Nº 24 Galv | E28: M2 | F28: 1114
B29: =B28+1 -> 22 | C29: Correa de hierro Tipo C | E29: M2 | F29: 356.83
B30: =B29+1 -> 23 | C30: Viga metálica Tipo C | E30: M2 | F30: 13140
B31: =B30+1 -> 24 | C31: Chapa lisa Nº 24 Prepintada | E31: M2 | F31: 5500
B32: =B31+1 -> 25 | C32: Chapa lisa Nº 24 Galv | E32: M2 | F32: 6060
B33: =B32+1 -> 26 | C33: Cumbrera de Chº Nº 24 | E33: ML | F33: 2191
B34: =B33+1 -> 27 | C34: Gancho J P/techo | E34: Un | F34: 290
... B71: =B70+1 -> 64 | C71: Brea solida | E71: Kg | F71: 36
B72: =B71+1 -> 65 | C72: Cera | E72: Kg
B73: =B72+1 -> 66 | C73: Mosaico Granítico 30x30 Color | E73: M2 | F73: 100
B74: =B73+1 -> 67 | C74: Zócalo Granitico 10x30 | E74: Ml | F74: 380
B75: =B74+1 -> 68 | C75: Pastina color | E75: Kg | F75: 305.58
B76: =B75+1 -> 69 | C76: Losetas de 40x40 C/relieves | E76: Nº | F76: 190
B77: =B76+1 -> 70 | C77: Losetas de 50x40 Atermico p/borde | E77: Nº | F77: 412
B78: =B77+1 -> 71 | C78: Sellador de juntas en tiras | E78: Ml | F78: 375
...

Sheet ANALISIS DE PRECIOS
A1: OBRA:
A3: Empresa:
B5: ANALISIS DE COSTOS | U5: 333
A6: Fecha:
A8: Item: | B8: COSTO HORARIO DE LA MANO DE OBRA
A9: Unidad: | B9: (Hs)
L10: FEBRERO/2004 | M10: AGOSTO/2003
A11: A: OFICIAL ALBAÑIL
A12: Nº | B12: DESIGNACION | C12: UNIDAD | D12: CANTIDAD | E12: PRECIO | F12: PRECIO | J12: OFICIAL
E13: UNITARIO | F13: TOTAL
B14: Jornal Básico | D14: 1 | E14: =+LISTA!F8 -> 631.9 | F14: =ROUND(D14*E14,2) -> 631.9 | J14: BASICO | L14: =+F14 -> 631.9 | M14: 1.56
B15: Asistencia Perfecta | D15: 0.18 | E15: =+E14 -> 631.9 | F15: =ROUND(D15*E15,2) -> 113.74 | J15: ASISTENCIA PERFECTA | K15: 0.18 | L15: =+L14*K15 -> 113.742 | M15: =+M14*K15 -> 0.2808
B16: PARCIAL | F16: =+F14+F15 -> 745.64 | J16: PARCIAL | L16: =+L14+L15 -> 745.642 | M16: =+M14+M15 -> 1.8408
B17: Cargas sociales | D17: 0.58 | E17: =+F16 -> 745.64 | F17: =ROUND(D17*E17,2) -> 432.47 | J17: FONDO DESEMPLEO | K17: 0.12 | L17: =+$K17*$L$16 -> 89.47704 | M17: =+$K17*$M$16 -> 0.220896
B18: Seguro Obrero | D18: 0.0766 | E18: =E17 -> 745.64 | F18: =ROUND(D18*E18,2) -> 57.12 | J18: ART | K18: 0.0766 | L18: =+$K18*$L$16 -> 57.116177 | M18: =+$K18*$M$16 -> 0.14100528
B19: Ley Provincial 49 | D19: 0.005 | E19: =E18 -> 745.64 | F19: =ROUND(D19*E19,2) -> 3.73 | J19: APORTE PATRONAL JUBILACION | K19: 0.17 | L19: =+$K19*$L$16 -> 126.75914 | M19: =+$K19*$M$16 -> 0.312936
J20: OSPECON | K20: 0.06 | L20: =+$K20*$L$16 -> 44.73852 | M20: =+$K20*$M$16 -> 0.110448
F21: =SUM(F16:F19) -> 1238.96 | J21: CAUSAS CLIMATICAS | K21: 0.008 | L21: =+$K21*$L$16 -> 5.965136 | M21: =+$K21*$M$16 -> 0.0147264
C22: TOTAL | F22: =+F21 -> 1238.96 | J22: FONDO SALUD PUBLICA | K22: 0.005 | L22: =+$K22*$L$16 -> 3.72821 | M22: =+$K22*$M$16 -> 0.009204
J23: ENFERMEDAD | K23: 0.029 | L23: =+$K23*$L$16 -> 21.623618 | M23: =+$K23*$M$16 -> 0.0533832
J24: VACACIONES | K24: 0.0622 | L24: =+$K24*$L$16 -> 46.378932 | M24: =+$K24*$M$16 -> 0.11449776
A25: Item: | B25: COSTO HORARIO DE LA MANO DE OBRA | J25: S.A.C. | K25: 0.1112 | L25: =+$K25*$L$16 -> 82.91539 | M25: =+$K25*$M$16 -> 0.20469696
A26: Unidad: | B26: (Hs) | J26: VESTIMENTA | K26: 0.018 | L26: =+$K26*$L$16 -> 13.421556 | M26: =+$K26*$M$16 -> 0.0331344
J27: FERIADOS | K27: 0.002 | L27: =+$K27*$L$16 -> 1.491284 | M27: =+$K27*$M$16 -> 0.0036816
A28: B: AYUDANTE ALBAÑIL | J28: JORNAL DE APLICACION | L28: =SUM(L16:L27) -> 1239.257 | M28: =SUM(M16:M27) -> 3.0594096
A29: Nº | B29: DESIGNACION | C29: UNIDAD | D29: CANTIDAD | E29: PRECIO | F29: PRECIO | J29: FACTOR | L29: =+L28/L16 -> 1.662 | M29: =150/176 -> 0.85227273
E30: UNITARIO | F30: TOTAL | M30: =+M28+M29 -> 3.9116823 | N30: =+L28/M30 -> 316.80921
B31: Jornal Básico | D31: 1 | E31: =+LISTA!F9 -> 197.07 | F31: =ROUND(D31*E31,2) -> 197.07
B32: Asistencia Perfecta | D32: 0.18 | E32: =+E31 -> 197.07 | F32: =ROUND(D32*E32,2) -> 35.47
B33: PARCIAL | F33: =+F31+F32 -> 232.54 | J33: AYUDANTE
B34: Cargas sociales | D34: 0.58 | E34: =+F33 -> 232.54 | F34: =ROUND(D34*E34,2) -> 134.87
B35: Seguro Obrero | D35: 0.0766 | E35: =E34 -> 232.54 | F35: =ROUND(D35*E35,2) -> 17.81 | J35: BASICO | L35: =+F31 -> 197.07 | M35: 1.48
B36: Ley Provincial 49 | D36: 0.005 | E36: =E35 -> 232.54 | F36: =ROUND(D36*E36,2) -> 1.16 | J36: ASISTENCIA PERFECTA | K36: =+K15 -> 0.18 | L36: =+L35*K36 -> 35.4726 | M36: =+M35*K36 -> 0.2664
J37: PARCIAL | K37: =+K16 -> 0 | L37: =+L35+L36 -> 232.5426 | M37: =+M35+M36 -> 1.7464
F38: =SUM(F33:F37) -> 386.38 | J38: FONDO DESEMPLEO | K38: =+K17 -> 0.12 | L38: =+$K38*$L$37 -> 27.905112 | M38: =+$K38*$M$37 -> 0.209568
C39: TOTAL | F39: =+F38 -> 386.38 | J39: ART | K39: =+K18 -> 0.0766 | L39: =+$K39*$L$37 -> 17.812763 | M39: =+$K39*$M$37 -> 0.13377424
J40: APORTE PATRONAL JUBILACION | K40: =+K19 -> 0.17 | L40: =+$K40*$L$37 -> 39.532242 | M40: =+$K40*$M$37 -> 0.296888
A41: Item: | B41: LIMPIEZA Y NIVELACION DEL TERRENO | J41: OSPECON | K41: =+K20 -> 0.06 | L41: =+$K41*$L$37 -> 13.952556 | M41: =+$K41*$M$37 -> 0.104784
A42: Unidad: | B42: (GL) | J42: CAUSAS CLIMATICAS | K42: =+K21 -> 0.008 | L42: =+$K42*$L$37 -> 1.8603408 | M42: =+$K42*$M$37 -> 0.0139712
J43: FONDO SALUD PUBLICA | K43: =+K22 -> 0.005 | L43: =+$K43*$L$37 -> 1.162713 | M43: =+$K43*$M$37 -> 0.008732
...

Sheet Computo
A1: Computo de obra
A2: Segovia Joaquin Ezequiel
A4: RUBROS | B4: Designacion | E4: N° de partes | G4: Largo | H4: Ancho | I4: Altura | J4: Unidad | K4: Parcial | L4: Total
A5: 1 | B5: EXCAVACIONES
A6: 1.1 | B6: Exc. de V.Encadenado inferior | L6: 38.351358
A7: 1.2 | B7: V.E.1 | E7: 1 | G7: 6 | H7: 0.2 | I7: 0.2 | J7: m3 | K7: =G7*H7*I7 -> 0.24
A8: 1.3 | B8: V.E.2 | E8: 3 | G8: 3 | H8: 0.2 | I8: 0.2 | J8: m3 | K8: =G8*H8*I8 -> 0.12
A9: 1.4 | B9: V.E.3 | E9: 3 | G9: 4 | H9: 0.2 | I9: 0.2 | J9: m3 | K9: =G9*H9*I9 -> 0.16
A10: 1.5 | B10: V.E.4 | E10: 2 | G10: 20.7 | H10: 0.2 | I10: 0.2 | J10: m3 | K10: =G10*H10*I10 -> 0.828
A11: 1.6 | B11: V.E.5 | E11: 1 | G11: 12 | H11: 0.2 | I11: 0.2 | J11: m3 | K11: =G11*H11*I11 -> 0.48
A12: 1.7 | B12: V.E.6 | E12: 6 | G12: 3.4 | H12: 0.2 | I12: 0.2 | J12: m3 | K12: =G12*H12*I12 -> 0.136
A13: 1.8 | B13: V.E.7 | E13: 3 | G13: 2.4 | H13: 0.2 | I13: 0.2 | J13: m3 | K13: =G13*H13*I13 -> 0.096
A14: 1.9 | B14: V.E.8 | E14: 3 | G14: 2.2 | H14: 0.2 | I14: 0.2 | J14: m3 | K14: =G14*H14*I14 -> 0.088
A15: 2 | B15: V.E.9 | E15: 4 | G15: 2.8 | H15: 0.2 | I15: 0.2 | J15: m3 | K15: =G15*H15*I15 -> 0.112
A16: 2.1 | B16: V.E.10 | E16: 2 | G16: 3.5 | H16: 0.2 | I16: 0.2 | J16: m3 | K16: =G16*H16*I16 -> 0.14
A17: 2.2 | B17: V.E.11 | E17: 2 | G17: 5.1 | H17: 0.2 | I17: 0.2 | J17: m3 | K17: =G17*H17*I17 -> 0.204
A18: 2.3 | B18: V.E.12 | E18: 2 | G18: 1.9 | H18: 0.2 | I18: 0.2 | J18: m3 | K18: =G18*H18*I18 -> 0.076
A19: 2.4 | B19: V.E.13 | E19: 1 | G19: 3.1 | H19: 0.2 | I19: 0.2 | J19: m3 | K19: =G19*H19*I19 -> 0.124
A20: 2.5 | B20: V.E.14 | E20: 1 | G20: 3.8 | H20: 0.2 | I20: 0.2 | J20: m3 | K20: =G20*H20*I20 -> 0.152 | L20: =K7+K8+K9+K10+K11+K12+K13+K14+K15+K16+K17+K18+K19+K20 -> 2.956 | N20: =SUM(E7:E20) -> 34 | P20: =N20*L20 -> 100.504
A21: 2.6 | B21: Exc. de pilotines | E21: 137 | H21: 0.0314 | I21: 1.31 | J21: m3 | K21: =E21*H21*I21 -> 5.635358 | L21: =K21 -> 5.635358
A22: 2.7 | B22: Exc. de Zapatas aisladas 2 | E22: 22 | G22: 0.8 | H22: 0.8 | I22: 1.5 | J22: m3 | K22: =G22*H22*I22*E22 -> 21.12
A23: 2.8 | B23: Exc. de Zaptas aisladas 1 | E23: 4 | G23: 1.2 | H23: 1.2 | I23: 1.5 | J23: m3 | K23: =G23*H23*I23*E23 -> 8.64 | L23: =K22+K23 -> 29.76
A24: 2.9 | B24: HORMIGON ARMADO | L24: =K33+K25+K26+K27+K28+K29+K30 -> 366.21269
A25: 3 | B25: H°A° Viga de encadenado inf. | E25: tomar igual valor para excavacion | J25: m3 | K25: =L20 -> 2.956
A26: 3.1 | B26: H°A° para pilotines | E26: tomar igual valor para excavacion | J26: m3 | K26: =K21 -> 5.635358
A27: 3.2 | B27: H°A° para fondos 1 | E27: 2 | G27: 1.2 | H27: 1.2 | I27: 0.2 | J27: m3 | K27: =G27*H27*I27*E27 -> 0.576 | L27: =K27+K29 -> 0.832
A28: 3.3 | B28: H°A° para piramidal 1 | E28: 2 | G28: 1.2 | H28: 1.2 | I28: 0.1166667 | J28: m3 | K28: =G28*H28*I28*E28 -> 0.3360001 | L28: =K28+K30 -> 0.48533347
A29: 3.4 | B29: H°A° para fondos 2 | E29: 2 | G29: 0.8 | H29: 0.8 | I29: 0.2 | J29: m3 | K29: =G29*H29*I29*E29 -> 0.256
A30: 3.5 | B30: H°A° para piramidal 2 | E30: 2 | G30: 0.8 | H30: 0.8 | I30: 0.1166667 | J30: m3 | K30: =G30*H30*I30*E30 -> 0.14933338
A31: 3.6 | B31: H°A° para columnas
A32: 3.7 | B32: H°A° para vigas
A33: 3.8 | B33: H°A° para losas | E33: 1 | G33: 57.1 | H33: 31.2 | I33: 0.2 | J33: m3 | K33: =G33*H33*I33 -> 356.304
A34: 3.9
A35: 4 | B35: MAMPOSTERIA
A36: 4.1 | B36: Mamposteria L.C 0.20 cm | L36: =K37+K38+K39+K40+K41+K42+K43+K44+K45+K46+K47+K41+K49+K50+K51+K52+K53+K54 -> 165.532
A37: 4.2 | B37: Pared 1 | E37: 4 | G37: 13.7 | H37: 0.2 | I37: 3 | J37: m3 | K37: =G37*H37*I37*E37 -> 32.88
A38: 4.3 | B38: Pared 2 | E38: 3 | G38: 11.6 | H38: 0.2 | I38: 3 | J38: m3 | K38: =G38*H38*I38*E38 -> 20.88
A39: 4.4 | B39: Pared 3 | E39: 1 | G39: 7.5 | H39: 0.2 | I39: 3 | J39: m3 | K39: =G39*H39*I39 -> 4.5
A40: 4.5 | B40: Pared 4 | E40: 1 | G40: 5.5 | H40: 0.2 | I40: 3 | J40: m3 | K40: =G40*H40*I40 -> 3.3
A41: 4.6 | B41: Pared 5 | E41: 9 | G41: 3.4 | H41: 0.2 | I41: 3 | J41: m3 | K41: =G41*H41*I41*E41 -> 18.36
...

Sheet Presupuesto
C2: OBRA:
C4: Empresa:
D6: PLANILLA de COMPUTO y PRESUPUESTO
H8: Fecha:
C10: Nº | D10: DESIGNACION DE LAS OBRAS | E10: UNIDAD | F10: CANTIDAD | G10: PRECIO | H10: IMPORTE | J10: %
F11: TOTAL | G11: UNITARIO | H11: PARCIAL | I11: TOTAL | J11: INCIDENCIA
C12: 1 | D12: EXCAVACION | I12: =H13+H14+H15 -> 115884.92
C13: 1.1 | D13: Exc viga de encadenado inferior | E13: m3 | F13: =+Computo!L20 -> 2.956 | G13: =+'ANALISIS DE PRECIOS'!G203 -> 1545.52 | H13: =+F13*G13 -> 4568.5571
C14: 1.2 | D14: Exc para pilotines | E14: m3 | F14: =+Computo!L21 -> 5.635358 | G14: =+'ANALISIS DE PRECIOS'!G222 -> 11591.4 | H14: =+F14*G14 -> 65321.689
C15: 1.3 | D15: Exc para zapatas aisladas | E15: m3 | F15: =+Computo!L23 -> 29.76 | G15: =+'ANALISIS DE PRECIOS'!G203 -> 1545.52 | H15: =+F15*G15 -> 45994.675
C16: 1.4 | D16: HORMIGON ARMADO | I16: =H17+H21+H22+H18 -> 1716684.6
C17: 1.5 | D17: H°A° Viga encadenado inf | E17: m3 | F17: =+Computo!K25 -> 2.956 | G17: =+'ANALISIS DE PRECIOS'!G290 -> 160846.1 | H17: =+F17*G17 -> 475461.07
C18: 1.6 | D18: H°A° para pilotines | E18: m3 | F18: =+Computo!K26 -> 5.635358 | G18: =+'ANALISIS DE PRECIOS'!G244 -> 152259.5 | H18: =+F18*G18 -> 858036.79
C19: 1.7 | D19: H°A°para fondos | E19: m3 | F19: =+Computo!L27 -> 0.832
C20: 1.8 | D20: H°A° para piramidal | E20: m3 | F20: =+Computo!L28 -> 0.48533347
C21: 1.9 | D21: H°A° para columnas | E21: m3 | G21: =+'ANALISIS DE PRECIOS'!G267 -> 222340.6 | H21: =+G21 -> 222340.6
C22: 2 | D22: H°A° para vigas | E22: m3 | G22: =+'ANALISIS DE PRECIOS'!G290 -> 160846.1 | H22: =+G22 -> 160846.1
C23: 2.1 | D23: H°A° para losa | E23: m3 | F23: =+Computo!K33 -> 356.304
C24: 2.2 | D24: MAMPOSTERIA | I24: =+H25+H26 -> 3530704.5
C25: 2.3 | D25: Mamposteria de ladrillo comun ext 0.20m | E25: m3 | F25: =+Computo!L36 -> 165.532 | G25: =+'ANALISIS DE PRECIOS'!G330 -> 19721.05 | H25: =+F25*G25 -> 3264464.8
C26: 2.4 | D26: Mamposteria de ladrillo comun 0.15m | E26: m3 | F26: =+Computo!L55 -> 2.475 | G26: =+'ANALISIS DE PRECIOS'!G374 -> 107571.57 | H26: =+F26*G26 -> 266239.64
C27: 2.5 | D27: CAPA AISLADORA DOBLE SELLADA | I27: =+H28 -> 237873.04
C28: 2.6 | D28: CAPA AISLADORA DOBLE SELLADA | E28: m2 | F28: =+Computo!O62 -> 85.0245 | G28: =+'ANALISIS DE PRECIOS'!G458 -> 2797.7 | H28: =+F28*G28 -> 237873.04
C29: 2.7
C30: 2.8 | D30: CONTRAPISO | I30: =+H31 -> 366692.12
C31: 2.9 | D31: Locales | E31: m2 | F31: =+Computo!L66 -> 212.5 | G31: =+'ANALISIS DE PRECIOS'!G771 -> 1725.61 | H31: =+F31*G31 -> 366692.12
C32: 3 | D32: PISO | I32: =+H33 -> 690737.62
C33: 3.1 | D33: Ceramico 30x30 | E33: m2 | F33: =+Computo!L76 -> 212.5 | G33: =+'ANALISIS DE PRECIOS'!G838 -> 3250.53 | H33: =+F33*G33 -> 690737.62
C34: 3.2 | D34: ZOCALO | I34: =+H35 -> 190831.59
C35: 3.3 | D35: Zocalo 30x30 | E35: ml | F35: =+Computo!L78 -> 184.3 | G35: =+'ANALISIS DE PRECIOS'!G926 -> 1035.44 | H35: =+F35*G35 -> 190831.59
C36: 3.4 | D36: REVOQUE | I36: =+H37+H38 -> 4544660.1
C37: 3.5 | D37: Revoque exterior completo | E37: m2 | F37: =+Computo!L81 -> 483.94 | G37: =+'ANALISIS DE PRECIOS'!G602 -> 7637.03 | H37: =+F37*G37 -> 3695864.3
C38: 3.6 | D38: Revoque interior completo | E38: m2 | F38: =+Computo!L99 -> 656.8 | G38: =+'ANALISIS DE PRECIOS'!G558 -> 1292.32 | H38: =+F38*G38 -> 848795.78
C39: 3.7 | D39: PINTURA | I39: =+H40+H41+H44+H45 -> 2501163.4
C40: 3.8 | D40: Pintura latex exterior | E40: m2 | F40: =+Computo!K122 -> 483.94 | G40: =+'ANALISIS DE PRECIOS'!G1089 -> 2561.25 | H40: =+F40*G40 -> 1239491.3
C41: 3.9 | D41: Pintura latex interior | E41: m2 | F41: =+Computo!K123 -> 656.8 | G41: =+'ANALISIS DE PRECIOS'!G1069 -> 1913.51 | H41: =+F41*G41 -> 1256793.4
C42: 4 | D42: Pintura Ventana | E42: m2
C43: 4.1 | D43: Pintura Puerta Ext | E43: m2
C44: 4.2 | D44: Pintura Puerta Int | E44: m2 | F44: =+Computo!K124 -> 1.827 | G44: =+'ANALISIS DE PRECIOS'!G1147 -> 1413.71 | H44: =+F44*G44 -> 2582.8482
C45: 4.3 | D45: Pintura Puerta Int | E45: m2 | F45: =+Computo!K125 -> 1.624 | G45: =+'ANALISIS DE PRECIOS'!G1147 -> 1413.71 | H45: =+F45*G45 -> 2295.865
...

Sheet Hoja1
